Workbook
Name Slicer_State: #N/A

Sheet Start here
D3: Is Nostalgia Coloring Our Memory?
C6: Back in 1976, we did not have the internet. We were still on landline.
C8: Today, we have myriad digital devices such as iPads and cells phones to go along with the
C9: internet. We can order online, we can stream shows, we can search for information at our
C10: fingertips. And now, we can look forward to all of the wonders (or doom?) that AI can bring
C11: us.
C13: So, let's compare the 250th anniversary against the 200th anniversary in 1976. Was 1976
C14: really better days or is nostalgia fooling us?
C16: Since we can do a comparison on so many facets, I'm going to focus on a few selected items:
C17: unemployment, inflation and weather.
C19: Let's see what the data tells us.
C21: Index of tabs:
C22: Unemployment: compares 1976 and 2026 unemployment rate, both at the national level
... C31: So, what do you think? Is 2026 better than 1976? The numbers seem to suggest so.

Sheet Unemployment
D2: US Unemployment Rate | M2: State Unemployment Rate
M4: =_xlfn.XLOOKUP('Pivot Tables'!K11,'State names and code'!C3:C52,'State names and code'!E3:E52,,0) -> Alaska
D5: 200th anniversary | H5: 250th anniversary | M5: 200th anniversary | Q5: 250th anniversary | T5: Pick your state
D6: =+'Pivot Tables'!$B$12 -> 27912 | H6: =+'Pivot Tables'!$B$13 -> 46174 | M6: =+'Pivot Tables'!$J$14 -> 27912 | Q6: =+'Pivot Tables'!$J$15 -> 46143
D7: 1976 | H7: 2026 | M7: 1976 | Q7: 2026
D8: ='Pivot Tables'!C12 -> 7.6 | H8: ='Pivot Tables'!C13 -> 4.2 | M8: ='Pivot Tables'!K14 -> 7.1 | Q8: ='Pivot Tables'!K15 -> 4.6
D13: Source: | M13: Source:
D14: =+'Pivot Tables'!B3 -> US U3 Unemployment | M14: =+'Pivot Tables'!J3 -> State U3 Unemployment
D15: =+'Pivot Tables'!B4 -> Seasonally Adjusted | M15: =+'Pivot Tables'!J4 -> Seasonally Adjusted
D16: =+'Pivot Tables'!B5 -> FRED | M16: =+'Pivot Tables'!J5 -> FRED
D18: =+'Pivot Tables'!B7 -> Unemployment Rate (UNRATE) | FRED | St. Louis Fed | M18: =+'Pivot Tables'!J7 -> Unemployment Rate in Alaska (AKUR) | FRED | St. Louis Fed
D19: =+'Pivot Tables'!B8 -> https://fred.stlouisfed.org/series/UNRATE/ | M19: =+'Pivot Tables'!J8 -> https://fred.stlouisfed.org/series/AKUR/
D24: It looks like the states on the West Coast had higher unemployment rates both in 1976 and 2026. Does that mean they generally have higher unemployment rates?
D25: Do some states have persistent unemployment?
D52: Here's the usual pushback against "rosy" picture: Labor Force Participation Rate
D55: Some people often argue against the unemployment rate as being unduly positive and often turn to the Labor Force Participation Rate.
D56: Labor Force Participation Rate: This metric represents the proportion of eligible population that is either working or actively looking for work. It is shown as a
D57: percentage of the non-institutional population.
D60: 200th anniversary | H60: 250th anniversary
D61: =+'Pivot Tables'!$B$12 -> 27912 | H61: =+'Pivot Tables'!$B$13 -> 46174
D62: 1976 | H62: 2026 | L62: !
D63: ='Pivot Tables'!AV12 -> 61.5 | H63: ='Pivot Tables'!AV13 -> 61.5
M64: No change!
D68: Source:
D69: =+'Pivot Tables'!AU3 -> Labor Force Participation Rate (CIVPART)
D70: =+'Pivot Tables'!AU4 -> Seasonally Adjust
D71: =+'Pivot Tables'!AU5 -> FRED
D72: =+'Pivot Tables'!AU6 -> Monthly
D74: =+'Pivot Tables'!AU8 -> Labor Force Participation Rate (CIVPART) | FRED | St. Louis Fed
D75: ='Pivot Tables'!AU9 -> https://fred.stlouisfed.org/series/CIVPART/
B78: Open the "+" to see more
D82: BUT…
D84: Let's look at it from another angle - through a longer span of time.
O88: Labor force participation peaked in early 2000 and began to decline.
O89: Next steep continuous decline around 2007 - the Great Recession.
O90: That decline began to flatlined around 2015.
O91: Then COVID hit 2020.
O92: Next peak around 8/2023 and has been slowly declining since.
O94: ChatGPT appeared end of 2022.
O97: Source:
...

Sheet Inflation
D3: US Inflation (CPI )
D4: Percent change from year ago
D6: 200th anniversary | H6: 250th anniversary
D7: =+'Pivot Tables'!$AE$12 -> 27912 | H7: =+'Pivot Tables'!$AE$13 -> 46143
D8: 1976 | H8: 2026
D9: ='Pivot Tables'!AF12 -> 5.98131 | H9: ='Pivot Tables'!AF13 -> 4.16661
D14: Source:
D15: =+'Pivot Tables'!B4 -> Seasonally Adjusted
D16: =+'Pivot Tables'!B5 -> FRED
D17: =+'Pivot Tables'!AE6 -> Monthly, Percent Change from year ago
D19: =+'Pivot Tables'!AE8 -> Consumer Price Index for All Urban Consumers: All Items in U.S. City Average (CPIAUCSL) | FRED | St. Louis Fed
D21: =+'Pivot Tables'!AE9 -> https://fred.stlouisfed.org/series/CPIAUCSL
D26: However…
D29: Those numbers are "percent change from a year ago".
D30: If we depict inflation in terms of "dollars", where around 1982-1984 it is around $100…
D31: There is a significant jump in CPI for housing, transportation, food & beverage, translating into overall pain. Most importantly, the slope seems steeper.
D34: 1947-2026 | M34: 1967-2026 | V34: 1947-2026
D52: Source: | M52: Source: | V52: Source:
D53: =+'Pivot Tables'!BF4 -> Seasonally Adjust | M53: =+'Pivot Tables'!BP4 -> Seasonally Adjust | V53: =+'Pivot Tables'!BZ4 -> Seasonally Adjust
D54: =+'Pivot Tables'!BF5 -> FRED | M54: =+'Pivot Tables'!BP5 -> FRED | V54: =+'Pivot Tables'!BZ5 -> FRED
D55: =+'Pivot Tables'!BF6 -> Monthly, Index 1982-1984=100 | M55: =+'Pivot Tables'!BP6 -> Monthly, Index 1982-1984=100 | V55: =+'Pivot Tables'!BZ6 -> Monthly, Index 1982-1984=100
D57: =+'Pivot Tables'!BF8 -> Consumer Price Index for All Urban Consumers: All Items in U.S. City Average (CPIAUCSL) | FRED | St. Louis Fed | M57: =+'Pivot Tables'!BP8 -> Consumer Price Index for All Urban Consumers: Housing in U.S. City Average (CPIHOSSL) | FRED | St. Louis Fed | V57: =+'Pivot Tables'!BZ8 -> Consumer Price Index for All Urban Consumers: Transportation in U.S. City Average (CPITRNSL) | FRED | St. Louis Fed
D59: =+'Pivot Tables'!BF9 -> https://fred.stlouisfed.org/series/CPIAUCSL | M59: =+'Pivot Tables'!BP9 -> https://fred.stlouisfed.org/series/CPIHOSSL | V59: =+'Pivot Tables'!BZ9 -> https://fred.stlouisfed.org/series/CPITRNSL
D63: 1967-2026 | M63: 1947-2026 | V63: 1993-2026
D80: Source: | M80: Source: | V80: Source:
D81: =+'Pivot Tables'!CK4 -> Seasonally Adjusted | M81: =+'Pivot Tables'!CV4 -> Seasonally Adjusted | V81: =+'Pivot Tables'!DG4 -> Seasonally Adjusted
D82: =+'Pivot Tables'!CK5 -> FRED | M82: =+'Pivot Tables'!CV5 -> FRED | V82: =+'Pivot Tables'!DG5 -> FRED
D83: =+'Pivot Tables'!CK6 -> Monthly, Index 1982-1984=100 | M83: =+'Pivot Tables'!CV6 -> Monthly, Index 1982-1984=100 | V83: =+'Pivot Tables'!DG6 -> Monthly, Index 1997=100
D85: =+'Pivot Tables'!CK8 -> Consumer Price Index for All Urban Consumers: Food and Beverages in U.S. City Average (CPIFABSL) | FRED | St. Louis Fed | M85: =+'Pivot Tables'!CV8 -> Consumer Price Index for All Urban Consumers: Medical Care in U.S. City Average (CPIMEDSL) | FRED | St. Louis Fed | V85: =+'Pivot Tables'!DG8 -> Consumer Price Index for All Urban Consumers: Education and Communication in U.S. City Average (CPIEDUSL) | FRED | St. Louis Fed
D87: =+'Pivot Tables'!CK9 -> https://fred.stlouisfed.org/series/CPIFABSL | M87: =+'Pivot Tables'!CV9 -> https://fred.stlouisfed.org/series/CPIMEDSL | V87: =+'Pivot Tables'!DG9 -> https://fred.stlouisfed.org/series/CPIEDUSL/
B90: Open the "+" to see more

Sheet Interest Rates
D3: Interest Rates
D6: 200th anniversary | H6: 250th anniversary
D7: =+'Pivot Tables'!$AN$12 -> 27942 | H7: =+'Pivot Tables'!$AN$13 -> 46174
D8: 1976 | H8: 2026
D9: ='Pivot Tables'!AO12 -> 5.31 | H9: ='Pivot Tables'!AO13 -> 3.63
D14: Source:
D15: =+'Pivot Tables'!AN3 -> Federal Funds Effective Rate (FEDFUNDS)
D16: =+'Pivot Tables'!AN4 -> Not seasonally adjusted
D17: =+'Pivot Tables'!AN5 -> FRED
D18: =+'Pivot Tables'!AN6 -> Monthly
D20: =+'Pivot Tables'!AN8 -> Federal Funds Effective Rate (FEDFUNDS) | FRED | St. Louis Fed
D21: =+'Pivot Tables'!AN9 -> https://fred.stlouisfed.org/series/FEDFUNDS
D25: The pushback…
D27: Housing has become expensive, especially for first time buyers, who have been locked out of the market.
D29: Here's an estimated mortgage debt burden as a percentage of the disposable income:
D32: 200th anniversary | H32: 250th anniversary
D33: Q2 1976 | H33: Q2 2026
D34: 1976 | H34: 2026
D35: ='Pivot Tables'!FM13 -> 0.03237926 | H35: ='Pivot Tables'!FM14 -> 0.037922309 | K35: These percentages appear to validate the current pain in the housing market.
K36: For debt burden over the years, please scroll down and see chart
D41: Sources:
D42: 1 | K42: 2 | R42: 3
D43: ='Pivot Tables'!EJ3 -> Freddie Mac, 30-Year Fixed Rate Mortgage Average in the United States (MORTGAGE30US) | K43: =+'Pivot Tables'!ER3 -> Board of Governors of the Federal Reserve System (US), Households and Nonprofit Organizations; One-to-Four-Family Residential Mortgages (HMLBSHNO) | R43: ='Pivot Tables'!FE3 -> Disposable Personal Income (DSPI)
D44: ='Pivot Tables'!EJ4 -> Percent, not seasonally adjusted | K44: ='Pivot Tables'!ER4 -> Millions of dollars, not seasonally adjusted | R44: ='Pivot Tables'!FE4 -> Billions of dollars, seasonally adjusted
D45: ='Pivot Tables'!EJ5 -> FRED (Freddie Mac) | K45: ='Pivot Tables'!ER5 -> FRED | R45: ='Pivot Tables'!FE5 -> FRED
D46: ='Pivot Tables'!EJ6 -> Weekly | K46: ='Pivot Tables'!ER6 -> Quarterly | R46: ='Pivot Tables'!FE6 -> Monthly
D48: =+'Pivot Tables'!EJ8 -> 30-Year Fixed Rate Mortgage Average in the United States (MORTGAGE30US) | FRED | St. Louis Fed | K48: ='Pivot Tables'!ER8 -> Households and Nonprofit Organizations; One-to-Four-Family Residential Mortgages; Liability, Level (HMLBSHNO) | FRED | St. Louis Fed | R48: ='Pivot Tables'!FE8 -> Disposable Personal Income (DSPI) | FRED | St. Louis Fed
D49: =+'Pivot Tables'!EJ9 -> https://fred.stlouisfed.org/series/MORTGAGE30US/ | K49: ='Pivot Tables'!ER9 -> https://fred.stlouisfed.org/series/HMLBSHNO | R49: ='Pivot Tables'!FE9 -> https://fred.stlouisfed.org/series/DSPI
D52: The math: Involves converting millions and billions to dollars and converting timing to Quarterly Q2 average
E54: Q2 Quarterly ave rate (MORTGAGE30US) x Q2 Mortgage Liability (HMLBSHNO) $
E55: Q2 Quarterly ave Disposable Personal Income (DSPI) $
B58: Open the "+" to see more
D61: The long view…
D63: Here's a look at debt burden over the years. Since the nadir of Qtr1 2021, debt burden has really climbed.
D64: Yet, between 1980 and 2004, debt burdened hovered between 4 to 5.5%, and today we tack just below it.
D99: Source:
D100: =+'Pivot Tables'!GQ3 -> Mortgage Burden
D101: ='Pivot Tables'!GQ4 -> Mortgage Payment/Disposable inc
D102: =+'Pivot Tables'!GJ5 -> FRED
D103: ='Pivot Tables'!GQ6 -> Quarterly
...

Sheet Conclusion
D3: It depends on where you sit
C5: Despite what the numbers tell you, most people regard unemployment and inflation to be terrible.
C6: If you operate in the AI arena, maybe job prospect is wonderful for you, but for the rest, the anxiety and longer unemployment stints may be the overriding factor.
C7: And inflation is really eating into the average person's pocketbook.
C9: The reactions stem from where you are sitting.
C11: But the comparisons to 1976 is interesting and surprising. For those who lived through that period, life didn't seem that bad.
C12: Childhood memories may be deceiving.
C14: And numbers alone may not be enough.

Sheet Pivot Tables
AU1: Employment - Labor Participation | BF1: Inflation - specific basket of goods | EJ1: Interest rates - 1976 vs 2026 - Housing | FQ1: Interest rate - housing throughout the years | GU1: Graphing section | GZ1: Raw table
AU2: The "But…" portion
B3: US U3 Unemployment | J3: State U3 Unemployment | P3: US U3 Unemployment - for map for 1976 | W3: US U3 Unemployment - for map for 2026 | AE3: Consumer Price Index (CPI) for all Consumers | AN3: Federal Funds Effective Rate (FEDFUNDS) | AU3: Labor Force Participation Rate (CIVPART) | BA3: Labor Force Participation Rate (CIVPART) | BF3: Consumer Price Index (CPI) for all Consumers | BP3: Consumer Price Index for All Urban Consumers: Housing in U.S. City Average (CPIHOSSL) | BZ3: Consumer Price Index for All Urban Consumers: Transportation in U.S. City Average (CPITRNSL) | CK3: Consumer Price Index for All Urban Consumers: Food and Beverages in U.S. City Average (CPIFABSL) | CV3: Consumer Price Index for All Urban Consumers: Medical Care in U.S. City Average (CPIMEDSL) | DG3: Consumer Price Index for All Urban Consumers: Education and Communication in U.S. City Average (CPIEDUSL) | DS3: CPI Cost Weights Dec 2025 | DZ3: CPI Cost Weights Dec 1975 | EJ3: Freddie Mac, 30-Year Fixed Rate Mortgage Average in the United States (MORTGAGE30US) | ER3: Board of Governors of the Federal Reserve System (US), Households and Nonprofit Organizations; One-to-Four-Family Residential Mortgages (HMLBSHNO) | FE3: Disposable Personal Income (DSPI) | FL3: Mortgage Burden | FQ3: Freddie Mac, 30-Year Fixed Rate Mortgage Average in the United States | FY3: Board of Governors of the Federal Reserve System (US), Households and Nonprofit Organizations; One-to-Four-Family Residential Mortgages | GJ3: Disposable Personal Income (DSPI) | GQ3: Mortgage Burden | GZ3: Freddie Mac, 30-Year Fixed Rate Mortgage Average in the United States
B4: Seasonally Adjusted | J4: Seasonally Adjusted | P4: Seasonally Adjusted | W4: Seasonally Adjusted | AE4: Seasonally Adjust | AN4: Not seasonally adjusted | AU4: Seasonally Adjust | BA4: Seasonally Adjust | BF4: Seasonally Adjust | BP4: Seasonally Adjust | BZ4: Seasonally Adjust | CK4: Seasonally Adjusted | CV4: Seasonally Adjusted | DG4: Seasonally Adjusted | DS4: CPI-U | DZ4: CPI-U | EJ4: Percent, not seasonally adjusted | ER4: Millions of dollars, not seasonally adjusted | FE4: Billions of dollars, seasonally adjusted | FL4: Mortgage Payment/Disposable inc | FQ4: Percent, not seasonally adjusted | FY4: Millions of dollars, not seasonally adjusted | GJ4: Billions of dollars, seasonally adjusted | GQ4: Mortgage Payment/Disposable inc | GZ4: Percent, not seasonally adjusted
B5: FRED | J5: FRED | P5: FRED | W5: FRED | AE5: FRED | AN5: FRED | AU5: FRED | BA5: FRED | BF5: FRED | BP5: FRED | BZ5: FRED | CK5: FRED | CV5: FRED | DG5: FRED | DS5: BLS - Bureau of Labor Statistics | DZ5: BLS - Bureau of Labor Statistics | EJ5: FRED (Freddie Mac) | ER5: FRED | FE5: FRED | FQ5: FRED (Freddie Mac) | FY5: FRED | GJ5: FRED | GZ5: FRED (Freddie Mac)
AE6: Monthly, Percent Change from year ago | AN6: Monthly | AU6: Monthly | BA6: Monthly | BF6: Monthly, Index 1982-1984=100 | BP6: Monthly, Index 1982-1984=100 | BZ6: Monthly, Index 1982-1984=100 | CK6: Monthly, Index 1982-1984=100 | CV6: Monthly, Index 1982-1984=100 | DG6: Monthly, Index 1997=100 | DS6: Annual | DZ6: Annual | EJ6: Weekly | ER6: Quarterly | FE6: Monthly | FL6: Quarterly (Q2) | FQ6: Weekly | FY6: Quarterly | GJ6: Monthly | GQ6: Quarterly | GZ6: Weekly
B7: Unemployment Rate (UNRATE) | FRED | St. Louis Fed | J7: ="Unemployment Rate in "&_xlfn.XLOOKUP(K11,'State names and code'!C3:C52,'State names and code'!E3:E52,,0)&" ("&K11&"UR) | FRED | St. Louis Fed" -> Unemployment Rate in Alaska (AKUR) | FRED | St. Louis Fed | P7: 2nd set of queries/tables in Connections | W7: 3rd set of queries/tables in Connections
B8: https://fred.stlouisfed.org/series/UNRATE/ | J8: ="https://fred.stlouisfed.org/series/"&K11&"UR/" -> https://fred.stlouisfed.org/series/AKUR/ | P8: ="https://fred.stlouisfed.org/series/xxUR/" -> https://fred.stlouisfed.org/series/xxUR/ | W8: ="https://fred.stlouisfed.org/series/xxUR/" -> https://fred.stlouisfed.org/series/xxUR/ | AE8: Consumer Price Index for All Urban Consumers: All Items in U.S. City Average (CPIAUCSL) | FRED | St. Louis Fed | AN8: Federal Funds Effective Rate (FEDFUNDS) | FRED | St. Louis Fed | AU8: Labor Force Participation Rate (CIVPART) | FRED | St. Louis Fed | BA8: Labor Force Participation Rate (CIVPART) | FRED | St. Louis Fed | BF8: Consumer Price Index for All Urban Consumers: All Items in U.S. City Average (CPIAUCSL) | FRED | St. Louis Fed | BP8: Consumer Price Index for All Urban Consumers: Housing in U.S. City Average (CPIHOSSL) | FRED | St. Louis Fed | BZ8: Consumer Price Index for All Urban Consumers: Transportation in U.S. City Average (CPITRNSL) | FRED | St. Louis Fed | CK8: Consumer Price Index for All Urban Consumers: Food and Beverages in U.S. City Average (CPIFABSL) | FRED | St. Louis Fed | CV8: Consumer Price Index for All Urban Consumers: Medical Care in U.S. City Average (CPIMEDSL) | FRED | St. Louis Fed | DG8: Consumer Price Index for All Urban Consumers: Education and Communication in U.S. City Average (CPIEDUSL) | FRED | St. Louis Fed | DS8: CPI-U Cost Weights, December 2011-present (XLSX) | DZ8: Historical relative importance 1947-1986 (XLSX) | EJ8: 30-Year Fixed Rate Mortgage Average in the United States (MORTGAGE30US) | FRED | St. Louis Fed | ER8: Households and Nonprofit Organizations; One-to-Four-Family Residential Mortgages; Liability, Level (HMLBSHNO) | FRED | St. Louis Fed | FE8: Disposable Personal Income (DSPI) | FRED | St. Louis Fed | FQ8: 30-Year Fixed Rate Mortgage Average in the United States (MORTGAGE30US) | FRED | St. Louis Fed | FY8: Households and Nonprofit Organizations; One-to-Four-Family Residential Mortgages; Liability, Level (HMLBSHNO) | FRED | St. Louis Fed | GJ8: Disposable Personal Income (DSPI) | FRED | St. Louis Fed | GZ8: 30-Year Fixed Rate Mortgage Average in the United States (MORTGAGE30US) | FRED | St. Louis Fed
P9: where xx is the state abbreviation | W9: where xx is the state abbreviation | AE9: https://fred.stlouisfed.org/series/CPIAUCSL | AN9: https://fred.stlouisfed.org/series/FEDFUNDS | AU9: https://fred.stlouisfed.org/series/CIVPART/ | BA9: https://fred.stlouisfed.org/series/CIVPART/ | BF9: https://fred.stlouisfed.org/series/CPIAUCSL | BP9: https://fred.stlouisfed.org/series/CPIHOSSL | BZ9: https://fred.stlouisfed.org/series/CPITRNSL | CK9: https://fred.stlouisfed.org/series/CPIFABSL | CV9: https://fred.stlouisfed.org/series/CPIMEDSL | DG9: https://fred.stlouisfed.org/series/CPIEDUSL/ | DS9: https://www.bls.gov/web/cpi/cpi-u-historical-cost-weights.xlsx | DZ9: https://www.bls.gov/cpi/tables/relative-importance/historical-relative-importance-1947-1986.xlsx | EJ9: https://fred.stlouisfed.org/series/MORTGAGE30US/ | ER9: https://fred.stlouisfed.org/series/HMLBSHNO | FE9: https://fred.stlouisfed.org/series/DSPI | FQ9: https://fred.stlouisfed.org/series/MORTGAGE30US/ | FY9: https://fred.stlouisfed.org/series/HMLBSHNO | GJ9: https://fred.stlouisfed.org/series/DSPI | GZ9: https://fred.stlouisfed.org/series/MORTGAGE30US/
FL10: Mortgage payment | FM10: Mortgage burden | GQ10: Mortgage payment | GR10: Mortgage burden
B11: Row Labels | C11: US Unemploy Rate | J11: State | K11: AK | P11: observation_date | Q11: 27912 | W11: observation_date | X11: 46143 | AE11: Row Labels | AF11: Sum of CPI Percent Change | AN11: Row Labels | AO11: Sum of FEDFUNDS | AU11: Row Labels | AV11: Sum of Percent participation | BA11: Year | BB11: Percent Labor Participation | BF11: Row Labels | BG11: Sum of CPI | BP11: Row Labels | BQ11: Sum of CPI Housing | BZ11: Row Labels | CA11: Sum of CPI Transportation | CK11: Row Labels | CL11: Sum of CPI Food & Bev | CV11: Row Labels | CW11: Sum of CPI Medical | DG11: Row Labels | DH11: Sum of CPI Educ & Comms | DS11: Row Labels | DT11: CPI-U Code Description.Description | DU11: Weight | DZ11: Row Labels | EA11: Weight | EJ11: Row Labels | EK11: Average of 30yr Mortgage rates | ER11: Row Labels | ES11: Average of Mort Liab Mil$ | ET11: Average of Mort Liab $ | FE11: Row Labels | FF11: Average of Disposable Inc Bil$ | FG11: Average of Disp Inc $ | FL11: Rate*Liab | FM11: Payment/disp inc | FQ11: Row Labels | FR11: Average of 30yr Mortgage rates | FY11: Row Labels | FZ11: Average of Mort Liab Mil$ | GA11: Average of Mort Liab $ | GJ11: Row Labels | GK11: Average of Disposable Inc Bil$ | GL11: Average of Disp Inc $ | GO11: Build up for graphing | GQ11: Rate*Liab | GR11: Payment/disp inc | GZ11: Row Labels | HA11: Average of 30yr Mortgage rates
B12: 27912 | C12: 7.6 | S12: For Map | Z12: For Map | AE12: 27912 | AF12: 5.98131 | AN12: 27942 | AO12: 5.31 | AU12: 27912 | AV12: 61.5 | BA12: 17533 | BB12: 58.6 | BF12: 17168 | BG12: 21.48 | BP12: 24473 | BQ12: 30.5 | BZ12: 17168 | CA12: 17.9 | CK12: 24473 | CL12: 34.8 | CV12: 17168 | CW12: 13.2 | DG12: 33970 | DH12: 84.1 | DS12: H | DT12: Housing | DU12: 44.468 | DZ12: Housing | EA12: 33.998 | EJ12: Qtr2 | EK12: 7.5957692 | ER12: Qtr2 | ES12: 7230464 | ET12: 7230464000000 | FE12: Qtr2 | FF12: 12477.067 | FG12: 1.2477067e+13 | FK12: Qtr2 | FQ12: 1971 | FR12: 7.54175 | FY12: 1971 | FZ12: 302546.33 | GA12: 3.0254633e+11 | GJ12: 1971 | GK12: 839.66667 | GL12: 8.3966667e+11 | GP12: 1971 | GU12: Date | GV12: Mortgage Burden % | GZ12: 26025 | HA12: 7.33
B13: 46174 | C13: 4.2 | J13: Row Labels | K13: Sum of Unemployment Rate | P13: Row Labels | Q13: Sum of Unemployment Rate | S13: State | T13: Rate | W13: Row Labels | X13: Sum of Unemployment Rate | Z13: State | AA13: Rate | AE13: 46143 | AF13: 4.16661 | AN13: 46174 | AO13: 3.63 | AU13: 46174 | AV13: 61.5 | BA13: 17564 | BB13: 58.9 | BF13: 17199 | BG13: 21.62 | BP13: 24504 | BQ13: 30.5 | BZ13: 17199 | CA13: 17.9 | CK13: 24504 | CL13: 34.7 | CV13: 17199 | CW13: 13.3 | DG13: 34001 | DH13: 84.3 | DS13: T | DT13: Transportation | DU13: 16.318 | DZ13: Food | EA13: 24.675 | EJ13: 1976 | EK13: 8.7769231 | ER13: 1976 | ES13: 483990 | ET13: 483990000000 | FE13: 1976 | FF13: 1311.9333 | FG13: 1.3119333e+12 | FK13: 1976 | FL13: =(EK13/100)*ET13 -> 4.247943e+10 | FM13: =+(FL13/FG13) -> 0.03237926 | FQ13: Qtr2 | FR13: 7.4130769 | FY13: Qtr2 | FZ13: 295363 | GA13: 295363000000 | GJ13: Qtr2 | GK13: 826.36667 | GL13: 8.2636667e+11 | GO13: =IF(AND(LEFT(GP13,1)="Q",LEFT(GP12,1)<>"Q"),GP12&" - "&GP13,LEFT(GO12,4)&" - "&GP13) -> 1971 - Qtr2 | GP13: Qtr2 | GQ13: =(FR13/100)*GA13 -> 2.1895486e+10 | GR13: =+(GQ13/GL13) -> 0.026496091 | GU13: 1971 - Qtr2 | GV13: =_xlfn.XLOOKUP(GU13,$GO$13:$GO$288,$GR$13:$GR$288,"Not Found") -> 0.026496091 | GZ13: 26032 | HA13: 7.31
B14: Grand Total | C14: 11.8 | J14: 27912 | K14: 7.1 | P14: AK | Q14: 7.1 | S14: =+P14 -> AK | T14: =+Q14 -> 7.1 | W14: AK | X14: 4.6 | Z14: =W14 -> AK | AA14: =X14 -> 4.6 | AE14: Grand Total | AF14: 10.14792 | AN14: Grand Total | AO14: 8.94 | AU14: Grand Total | AV14: 123 | BA14: 17593 | BB14: 58.5 | BF14: 17227 | BG14: 22 | BP14: 24532 | BQ14: 30.5 | BZ14: 17227 | CA14: 18.1 | CK14: 24532 | CL14: 34.7 | CV14: 17227 | CW14: 13.3 | DG14: 34029 | DH14: 84.6 | DS14: F | DT14: Food | DU14: 14.541 | DZ14: Health and recreation | EA14: 18.681 | EJ14: 2026 | EK14: 6.4146154 | ER14: 2026 | ES14: 13976938 | ET14: 13976938000000 | FE14: 2026 | FF14: 23642.2 | FG14: 23642200000000 | FK14: 2026 | FL14: =(EK14/100)*ET14 -> 8.9656682e+11 | FM14: =+(FL14/FG14) -> 0.037922309 | FQ14: Qtr3 | FR14: 7.6584615 | FY14: Qtr3 | FZ14: 302822 | GA14: 302822000000 | GJ14: Qtr3 | GK14: 838.8 | GL14: 838800000000 | GO14: =IF(AND(LEFT(GP14,1)="Q",LEFT(GP13,1)<>"Q"),GP13&" - "&GP14,LEFT(GO13,4)&" - "&GP14) -> 1971 - Qtr3 | GP14: Qtr3 | GQ14: =(FR14/100)*GA14 -> 23191506400 | GR14: =+(GQ14/GL14) -> 0.027648434 | GU14: 1971 - Qtr3 | GV14: =_xlfn.XLOOKUP(GU14,$GO$13:$GO$288,$GR$13:$GR$288,"Not Found") -> 0.027648434 | GZ14: 26039 | HA14: 7.31
J15: 46143 | K15: 4.6 | P15: AL | Q15: 6.5 | S15: =+P15 -> AL | T15: =+Q15 -> 6.5 | W15: AL | X15: 3 | Z15: =W15 -> AL | AA15: =X15 -> 3 | BA15: 17624 | BB15: 59 | BF15: 17258 | BG15: 22 | BP15: 24563 | BQ15: 30.6 | BZ15: 17258 | CA15: 18.3 | CK15: 24563 | CL15: 34.6 | CV15: 17258 | CW15: 13.4 | DG15: 34060 | DH15: 84.8 | DS15: M | DT15: Medical | DU15: 8.423 | DZ15: Transportation | EA15: 13.053 | EJ15: Grand Total | EK15: 7.5957692 | ER15: Grand Total | ES15: 7230464 | ET15: 7230464000000 | FE15: Grand Total | FF15: 12477.067 | FG15: 1.2477067e+13 | FQ15: Qtr4 | FR15: 7.5528571 | FY15: Qtr4 | FZ15: 309454 | GA15: 309454000000 | GJ15: Qtr4 | GK15: 853.83333 | GL15: 8.5383333e+11 | GO15: =IF(AND(LEFT(GP15,1)="Q",LEFT(GP14,1)<>"Q"),GP14&" - "&GP15,LEFT(GO14,4)&" - "&GP15) -> 1971 - Qtr4 | GP15: Qtr4 | GQ15: =(FR15/100)*GA15 -> 2.3372619e+10 | GR15: =+(GQ15/GL15) -> 0.027373748 | GU15: 1971 - Qtr4 | GV15: =_xlfn.XLOOKUP(GU15,$GO$13:$GO$288,$GR$13:$GR$288,"Not Found") -> 0.027373748 | GZ15: 26046 | HA15: 7.31
J16: Grand Total | K16: 11.7 | P16: AR | Q16: 6.9 | S16: =+P16 -> AR | T16: =+Q16 -> 6.9 | W16: AR | X16: 4.2 | Z16: =W16 -> AR | AA16: =X16 -> 4.2 | BA16: 17654 | BB16: 58.3 | BF16: 17288 | BG16: 21.95 | BP16: 24593 | BQ16: 30.7 | BZ16: 17288 | CA16: 18.3 | CK16: 24593 | CL16: 34.6 | CV16: 17288 | CW16: 13.5 | DG16: 34090 | DH16: 85.2 | DS16: E | DT16: Education and communication | DU16: 5.847 | DZ16: Apparel and upkeep | EA16: 9.217 | FQ16: 1972 | FR16: 7.3832692 | FY16: 1972 | FZ16: 329615 | GA16: 329615000000 | GJ16: 1972 | GK16: 900.83333 | GL16: 9.0083333e+11 | GO16: =IF(AND(LEFT(GP16,1)="Q",LEFT(GP15,1)<>"Q"),GP15&" - "&GP16,LEFT(GO15,4)&" - "&GP16) -> 1971 - 1972 | GP16: 1972 | GQ16: =(FR16/100)*GA16 -> 2.4336363e+10 | GR16: =+(GQ16/GL16) -> 0.027015389 | GU16: 1972 - Qtr1 | GV16: =_xlfn.XLOOKUP(GU16,$GO$13:$GO$288,$GR$13:$GR$288,"Not Found") -> 0.026796556 | GZ16: 26053 | HA16: 7.29
P17: AZ | Q17: 9.7 | S17: =+P17 -> AZ | T17: =+Q17 -> 9.7 | W17: AZ | X17: 4.8 | Z17: =W17 -> AZ | AA17: =X17 -> 4.8 | BA17: 17685 | BB17: 59.2 | BF17: 17319 | BG17: 22.08 | BP17: 24624 | BQ17: 30.7 | BZ17: 17319 | CA17: 18.4 | CK17: 24624 | CL17: 34.9 | CV17: 17319 | CW17: 13.5 | DG17: 34121 | DH17: 85.4 | DS17: R | DT17: Recreation | DU17: 5.136 | DZ17: Grand Total | EA17: 99.624 | FQ17: Qtr1 | FR17: 7.3492308 | FY17: Qtr1 | FZ17: 316038 | GA17: 316038000000 | GJ17: Qtr1 | GK17: 866.76667 | GL17: 8.6676667e+11 | GO17: =IF(AND(LEFT(GP17,1)="Q",LEFT(GP16,1)<>"Q"),GP16&" - "&GP17,LEFT(GO16,4)&" - "&GP17) -> 1972 - Qtr1 | GP17: Qtr1 | GQ17: =(FR17/100)*GA17 -> 2.3226362e+10 | GR17: =+(GQ17/GL17) -> 0.026796556 | GU17: 1972 - Qtr2 | GV17: =_xlfn.XLOOKUP(GU17,$GO$13:$GO$288,$GR$13:$GR$288,"Not Found") -> 0.027062978 | GZ17: 26060 | HA17: 7.38
P18: CA | Q18: 8.9 | S18: =+P18 -> CA | T18: =+Q18 -> 8.9 | W18: CA | X18: 5.3 | Z18: =W18 -> CA | AA18: =X18 -> 5.3 | BA18: 17715 | BB18: 59.3 | BF18: 17349 | BG18: 22.23 | BP18: 24654 | BQ18: 30.8 | BZ18: 17349 | CA18: 18.5 | CK18: 24654 | CL18: 35 | CV18: 17349 | CW18: 13.5 | DG18: 34151 | DH18: 85.6 | DS18: G | DT18: Goods and services | DU18: 2.901 | FQ18: Qtr2 | FR18: 7.3469231 | FY18: Qtr2 | FZ18: 324462 | GA18: 324462000000 | GJ18: Qtr2 | GK18: 880.83333 | GL18: 8.8083333e+11 | GO18: =IF(AND(LEFT(GP18,1)="Q",LEFT(GP17,1)<>"Q"),GP17&" - "&GP18,LEFT(GO17,4)&" - "&GP18) -> 1972 - Qtr2 | GP18: Qtr2 | GQ18: =(FR18/100)*GA18 -> 2.3837974e+10 | GR18: =+(GQ18/GL18) -> 0.027062978 | GU18: 1972 - Qtr3 | GV18: =_xlfn.XLOOKUP(GU18,$GO$13:$GO$288,$GR$13:$GR$288,"Not Found") -> 0.027340415 | GZ18: 26067 | HA18: 7.42
P19: CO | Q19: 5.6 | S19: =+P19 -> CO | T19: =+Q19 -> 5.6 | W19: CO | X19: 3.9 | Z19: =W19 -> CO | AA19: =X19 -> 3.9 | BA19: 17746 | BB19: 58.9 | BF19: 17380 | BG19: 22.4 | BP19: 24685 | BQ19: 30.9 | BZ19: 17380 | CA19: 18.5 | CK19: 24685 | CL19: 35.2 | CV19: 17380 | CW19: 13.6 | DG19: 34182 | DH19: 86 | DS19: A | DT19: Apparel | DU19: 2.367 | FQ19: Qtr3 | FR19: 7.4061538 | FY19: Qtr3 | FZ19: 334408 | GA19: 334408000000 | GJ19: Qtr3 | GK19: 905.86667 | GL19: 9.0586667e+11 | GO19: =IF(AND(LEFT(GP19,1)="Q",LEFT(GP18,1)<>"Q"),GP18&" - "&GP19,LEFT(GO18,4)&" - "&GP19) -> 1972 - Qtr3 | GP19: Qtr3 | GQ19: =(FR19/100)*GA19 -> 2.4766771e+10 | GR19: =+(GQ19/GL19) -> 0.027340415 | GU19: 1972 - Qtr4 | GV19: =_xlfn.XLOOKUP(GU19,$GO$13:$GO$288,$GR$13:$GR$288,"Not Found") -> 0.026875937 | GZ19: 26074 | HA19: 7.44
P20: CT | Q20: 9.3 | S20: =+P20 -> CT | T20: =+Q20 -> 9.3 | W20: CT | X20: 5.1 | Z20: =W20 -> CT | AA20: =X20 -> 5.1 | BA20: 17777 | BB20: 58.9 | BF20: 17411 | BG20: 22.84 | BP20: 24716 | BQ20: 31 | BZ20: 17411 | CA20: 18.7 | CK20: 24716 | CL20: 35.2 | CV20: 17411 | CW20: 13.7 | DG20: 34213 | DH20: 86.3 | DS20: Grand Total | DU20: 100.001 | FQ20: Qtr4 | FR20: 7.4307692 | FY20: Qtr4 | FZ20: 343552 | GA20: 343552000000 | GJ20: Qtr4 | GK20: 949.86667 | GL20: 9.4986667e+11 | GO20: =IF(AND(LEFT(GP20,1)="Q",LEFT(GP19,1)<>"Q"),GP19&" - "&GP20,LEFT(GO19,4)&" - "&GP20) -> 1972 - Qtr4 | GP20: Qtr4 | GQ20: =(FR20/100)*GA20 -> 2.5528556e+10 | GR20: =+(GQ20/GL20) -> 0.026875937 | GU20: 1973 - Qtr1 | GV20: =_xlfn.XLOOKUP(GU20,$GO$13:$GO$288,$GR$13:$GR$288,"Not Found") -> 0.027022766 | GZ20: 26081 | HA20: 7.46
P21: DE | Q21: 8.7 | S21: =+P21 -> DE | T21: =+Q21 -> 8.7 | W21: DE | X21: 5.1 | Z21: =W21 -> DE | AA21: =X21 -> 5.1 | BA21: 17807 | BB21: 58.7 | BF21: 17441 | BG21: 22.91 | BP21: 24746 | BQ21: 31 | BZ21: 17441 | CA21: 18.8 | CK21: 24746 | CL21: 35.3 | CV21: 17441 | CW21: 13.8 | DG21: 34243 | DH21: 86.5 | FQ21: 1973 | FR21: 8.0448077 | FY21: 1973 | FZ21: 366929 | GA21: 366929000000 | GJ21: 1973 | GK21: 1008.375 | GL21: 1008375000000 | GO21: =IF(AND(LEFT(GP21,1)="Q",LEFT(GP20,1)<>"Q"),GP20&" - "&GP21,LEFT(GO20,4)&" - "&GP21) -> 1972 - 1973 | GP21: 1973 | GQ21: =(FR21/100)*GA21 -> 2.9518732e+10 | GR21: =+(GQ21/GL21) -> 0.029273566 | GU21: 1973 - Qtr2 | GV21: =_xlfn.XLOOKUP(GU21,$GO$13:$GO$288,$GR$13:$GR$288,"Not Found") -> 0.027799234 | GZ21: 26088 | HA21: 7.52
P22: FL | Q22: 9.1 | S22: =+P22 -> FL | T22: =+Q22 -> 9.1 | W22: FL | X22: 4.8 | Z22: =W22 -> FL | AA22: =X22 -> 4.8 | BA22: 17838 | BB22: 58.7 | BF22: 17472 | BG22: 23.06 | BP22: 24777 | BQ22: 31.1 | BZ22: 17472 | CA22: 19 | CK22: 24777 | CL22: 35.4 | CV22: 17472 | CW22: 13.8 | DG22: 34274 | DH22: 86.8 | FQ22: Qtr1 | FR22: 7.4461538 | FY22: Qtr1 | FZ22: 351550 | GA22: 351550000000 | GJ22: Qtr1 | GK22: 968.7 | GL22: 968700000000 | GO22: =IF(AND(LEFT(GP22,1)="Q",LEFT(GP21,1)<>"Q"),GP21&" - "&GP22,LEFT(GO21,4)&" - "&GP22) -> 1973 - Qtr1 | GP22: Qtr1 | GQ22: =(FR22/100)*GA22 -> 2.6176954e+10 | GR22: =+(GQ22/GL22) -> 0.027022766 | GU22: 1973 - Qtr3 | GV22: =_xlfn.XLOOKUP(GU22,$GO$13:$GO$288,$GR$13:$GR$288,"Not Found") -> 0.030901469 | GZ22: 26095 | HA22: 7.52
P23: GA | Q23: 8 | S23: =+P23 -> GA | T23: =+Q23 -> 8 | W23: GA | X23: 3.4 | Z23: =W23 -> GA | AA23: =X23 -> 3.4 | BA23: 17868 | BB23: 59.1 | BF23: 17502 | BG23: 23.41 | BP23: 24807 | BQ23: 31.2 | BZ23: 17502 | CA23: 19.1 | CK23: 24807 | CL23: 35.5 | CV23: 17502 | CW23: 13.9 | DG23: 34304 | DH23: 87.2 | FQ23: Qtr2 | FR23: 7.65 | FY23: Qtr2 | FZ23: 361814 | GA23: 361814000000 | GJ23: Qtr2 | GK23: 995.66667 | GL23: 9.9566667e+11 | GO23: =IF(AND(LEFT(GP23,1)="Q",LEFT(GP22,1)<>"Q"),GP22&" - "&GP23,LEFT(GO22,4)&" - "&GP23) -> 1973 - Qtr2 | GP23: Qtr2 | GQ23: =(FR23/100)*GA23 -> 2.7678771e+10 | GR23: =+(GQ23/GL23) -> 0.027799234 | GU23: 1973 - Qtr4 | GV23: =_xlfn.XLOOKUP(GU23,$GO$13:$GO$288,$GR$13:$GR$288,"Not Found") -> 0.031379759 | GZ23: 26102 | HA23: 7.54
P24: HI | Q24: 9.1 | S24: =+P24 -> HI | T24: =+Q24 -> 9.1 | W24: HI | X24: 2.5 | Z24: =W24 -> HI | AA24: =X24 -> 2.5 | BA24: 17899 | BB24: 58.7 | BF24: 17533 | BG24: 23.68 | BP24: 24838 | BQ24: 31.3 | BZ24: 17533 | CA24: 19.6 | CK24: 24838 | CL24: 35.5 | CV24: 17533 | CW24: 14 | DG24: 34335 | DH24: 87.3 | FQ24: Qtr3 | FR24: 8.4569231 | FY24: Qtr3 | FZ24: 372134 | GA24: 372134000000 | GJ24: Qtr3 | GK24: 1018.4333 | GL24: 1.0184333e+12 | GO24: =IF(AND(LEFT(GP24,1)="Q",LEFT(GP23,1)<>"Q"),GP23&" - "&GP24,LEFT(GO23,4)&" - "&GP24) -> 1973 - Qtr3 | GP24: Qtr3 | GQ24: =(FR24/100)*GA24 -> 3.1471086e+10 | GR24: =+(GQ24/GL24) -> 0.030901469 | GU24: 1974 - Qtr1 | GV24: =_xlfn.XLOOKUP(GU24,$GO$13:$GO$288,$GR$13:$GR$288,"Not Found") -> 0.031005592 | GZ24: 26109 | HA24: 7.54
P25: IA | Q25: 4 | S25: =+P25 -> IA | T25: =+Q25 -> 4 | W25: IA | X25: 3.2 | Z25: =W25 -> IA | AA25: =X25 -> 3.2 | BA25: 17930 | BB25: 59 | BF25: 17564 | BG25: 23.67 | BP25: 24869 | BQ25: 31.4 | BZ25: 17564 | CA25: 19.5 | CK25: 24869 | CL25: 35.7 | CV25: 17564 | CW25: 14 | DG25: 34366 | DH25: 87.9 | FQ25: Qtr4 | FR25: 8.6261538 | FY25: Qtr4 | FZ25: 382218 | GA25: 382218000000 | GJ25: Qtr4 | GK25: 1050.7 | GL25: 1050700000000 | GO25: =IF(AND(LEFT(GP25,1)="Q",LEFT(GP24,1)<>"Q"),GP24&" - "&GP25,LEFT(GO24,4)&" - "&GP25) -> 1973 - Qtr4 | GP25: Qtr4 | GQ25: =(FR25/100)*GA25 -> 3.2970713e+10 | GR25: =+(GQ25/GL25) -> 0.031379759 | GU25: 1974 - Qtr2 | GV25: =_xlfn.XLOOKUP(GU25,$GO$13:$GO$288,$GR$13:$GR$288,"Not Found") -> 0.032830074 | GZ25: 26116 | HA25: 7.54
P26: ID | Q26: 5.5 | S26: =+P26 -> ID | T26: =+Q26 -> 5.5 | W26: ID | X26: 3.7 | Z26: =W26 -> ID | AA26: =X26 -> 3.7 | BA26: 17958 | BB26: 58.9 | BF26: 17593 | BG26: 23.5 | BP26: 24898 | BQ26: 31.5 | BZ26: 17593 | CA26: 19.6 | CK26: 24898 | CL26: 35.8 | CV26: 17593 | CW26: 14.1 | DG26: 34394 | DH26: 88.1 | FQ26: 1974 | FR26: 9.1871154 | FY26: 1974 | FZ26: 405254.25 | GA26: 405254250000 | GJ26: 1974 | GK26: 1100.775 | GL26: 1100775000000 | GO26: =IF(AND(LEFT(GP26,1)="Q",LEFT(GP25,1)<>"Q"),GP25&" - "&GP26,LEFT(GO25,4)&" - "&GP26) -> 1973 - 1974 | GP26: 1974 | GQ26: =(FR26/100)*GA26 -> 3.7231176e+10 | GR26: =+(GQ26/GL26) -> 0.033822694 | GU26: 1974 - Qtr3 | GV26: =_xlfn.XLOOKUP(GU26,$GO$13:$GO$288,$GR$13:$GR$288,"Not Found") -> 0.035466442 | GZ26: 26123 | HA26: 7.54
P27: IL | Q27: 6.6 | S27: =+P27 -> IL | T27: =+Q27 -> 6.6 | W27: IL | X27: 5.1 | Z27: =W27 -> IL | AA27: =X27 -> 5.1 | BA27: 17989 | BB27: 58.8 | BF27: 17624 | BG27: 23.82 | BP27: 24929 | BQ27: 31.6 | BZ27: 17624 | CA27: 19.9 | CK27: 24929 | CL27: 36 | CV27: 17624 | CW27: 14.3 | DG27: 34425 | DH27: 88.3 | FQ27: Qtr1 | FR27: 8.4623077 | FY27: Qtr1 | FZ27: 389858 | GA27: 389858000000 | GJ27: Qtr1 | GK27: 1064.0333 | GL27: 1.0640333e+12 | GO27: =IF(AND(LEFT(GP27,1)="Q",LEFT(GP26,1)<>"Q"),GP26&" - "&GP27,LEFT(GO26,4)&" - "&GP27) -> 1974 - Qtr1 | GP27: Qtr1 | GQ27: =(FR27/100)*GA27 -> 3.2990984e+10 | GR27: =+(GQ27/GL27) -> 0.031005592 | GU27: 1974 - Qtr4 | GV27: =_xlfn.XLOOKUP(GU27,$GO$13:$GO$288,$GR$13:$GR$288,"Not Found") -> 0.035995609 | GZ27: 26130 | HA27: 7.6
P28: IN | Q28: 5.8 | S28: =+P28 -> IN | T28: =+Q28 -> 5.8 | W28: IN | X28: 3.3 | Z28: =W28 -> IN | AA28: =X28 -> 3.3 | BA28: 18019 | BB28: 59 | BF28: 17654 | BG28: 24.01 | BP28: 24959 | BQ28: 31.7 | BZ28: 17654 | CA28: 19.9 | CK28: 24959 | CL28: 36.1 | CV28: 17654 | CW28: 14.3 | DG28: 34455 | DH28: 88.6 | FQ28: Qtr2 | FR28: 8.8869231 | FY28: Qtr2 | FZ28: 400439 | GA28: 400439000000 | GJ28: Qtr2 | GK28: 1083.9667 | GL28: 1.0839667e+12 | GO28: =IF(AND(LEFT(GP28,1)="Q",LEFT(GP27,1)<>"Q"),GP27&" - "&GP28,LEFT(GO27,4)&" - "&GP28) -> 1974 - Qtr2 | GP28: Qtr2 | GQ28: =(FR28/100)*GA28 -> 35586705900 | GR28: =+(GQ28/GL28) -> 0.032830074 | GU28: 1975 - Qtr1 | GV28: =_xlfn.XLOOKUP(GU28,$GO$13:$GO$288,$GR$13:$GR$288,"Not Found") -> 0.033524523 | GZ28: 26137 | HA28: 7.65
P29: KS | Q29: 4.1 | S29: =+P29 -> KS | T29: =+Q29 -> 4.1 | W29: KS | X29: 3.8 | Z29: =W29 -> KS | AA29: =X29 -> 3.8 | BA29: 18050 | BB29: 58.6 | BF29: 17685 | BG29: 24.15 | BP29: 24990 | BQ29: 31.9 | BZ29: 17685 | CA29: 20 | CK29: 24990 | CL29: 36.1 | CV29: 17685 | CW29: 14.4 | DG29: 34486 | DH29: 88.9 | FQ29: Qtr3 | FR29: 9.6061538 | FY29: Qtr3 | FZ29: 411381 | GA29: 411381000000 | GJ29: Qtr3 | GK29: 1114.2333 | GL29: 1.1142333e+12 | GO29: =IF(AND(LEFT(GP29,1)="Q",LEFT(GP28,1)<>"Q"),GP28&" - "&GP29,LEFT(GO28,4)&" - "&GP29) -> 1974 - Qtr3 | GP29: Qtr3 | GQ29: =(FR29/100)*GA29 -> 3.9517892e+10 | GR29: =+(GQ29/GL29) -> 0.035466442 | GU29: 1975 - Qtr2 | GV29: =_xlfn.XLOOKUP(GU29,$GO$13:$GO$288,$GR$13:$GR$288,"Not Found") -> 0.031385957 | GZ29: 26144 | HA29: 7.69
P30: KY | Q30: 5.5 | S30: =+P30 -> KY | T30: =+Q30 -> 5.5 | W30: KY | X30: 4.5 | Z30: =W30 -> KY | AA30: =X30 -> 4.5 | BA30: 18080 | BB30: 58.9 | BF30: 17715 | BG30: 24.4 | BP30: 25020 | BQ30: 32.1 | BZ30: 17715 | CA30: 21 | CK30: 25020 | CL30: 36.2 | CV30: 17715 | CW30: 14.5 | DG30: 34516 | DH30: 89.1 | FQ30: Qtr4 | FR30: 9.7930769 | FY30: Qtr4 | FZ30: 419339 | GA30: 419339000000 | GJ30: Qtr4 | GK30: 1140.8667 | GL30: 1.1408667e+12 | GO30: =IF(AND(LEFT(GP30,1)="Q",LEFT(GP29,1)<>"Q"),GP29&" - "&GP30,LEFT(GO29,4)&" - "&GP30) -> 1974 - Qtr4 | GP30: Qtr4 | GQ30: =(FR30/100)*GA30 -> 4.1066191e+10 | GR30: =+(GQ30/GL30) -> 0.035995609 | GU30: 1975 - Qtr3 | GV30: =_xlfn.XLOOKUP(GU30,$GO$13:$GO$288,$GR$13:$GR$288,"Not Found") -> 0.032503225 | GZ30: 26151 | HA30: 7.66
P31: LA | Q31: 6.7 | S31: =+P31 -> LA | T31: =+Q31 -> 6.7 | W31: LA | X31: 4.5 | Z31: =W31 -> LA | AA31: =X31 -> 4.5 | BA31: 18111 | BB31: 59.2 | BF31: 17746 | BG31: 24.43 | BP31: 25051 | BQ31: 32.3 | BZ31: 17746 | CA31: 21.3 | CK31: 25051 | CL31: 36.3 | CV31: 17746 | CW31: 14.6 | DG31: 34547 | DH31: 89.3 | FQ31: 1975 | FR31: 9.0471154 | FY31: 1975 | FZ31: 441074.75 | GA31: 441074750000 | GJ31: 1975 | GK31: 1221.7833 | GL31: 1.2217833e+12 | GO31: =IF(AND(LEFT(GP31,1)="Q",LEFT(GP30,1)<>"Q"),GP30&" - "&GP31,LEFT(GO30,4)&" - "&GP31) -> 1974 - 1975 | GP31: 1975 | GQ31: =(FR31/100)*GA31 -> 3.9904542e+10 | GR31: =+(GQ31/GL31) -> 0.032660899 | GU31: 1975 - Qtr4 | GV31: =_xlfn.XLOOKUP(GU31,$GO$13:$GO$288,$GR$13:$GR$288,"Not Found") -> 0.033267687 | GZ31: 26158 | HA31: 7.73
P32: MA | Q32: 9.8 | S32: =+P32 -> MA | T32: =+Q32 -> 9.8 | W32: MA | X32: 4.5 | Z32: =W32 -> MA | AA32: =X32 -> 4.5 | BA32: 18142 | BB32: 59.1 | BF32: 17777 | BG32: 24.36 | BP32: 25082 | BQ32: 32.4 | BZ32: 17777 | CA32: 21.4 | CK32: 25082 | CL32: 36.5 | CV32: 17777 | CW32: 14.5 | DG32: 34578 | DH32: 89.4 | FQ32: Qtr1 | FR32: 9.1684615 | FY32: Qtr1 | FZ32: 424313 | GA32: 424313000000 | GJ32: Qtr1 | GK32: 1160.4333 | GL32: 1.1604333e+12 | GO32: =IF(AND(LEFT(GP32,1)="Q",LEFT(GP31,1)<>"Q"),GP31&" - "&GP32,LEFT(GO31,4)&" - "&GP32) -> 1975 - Qtr1 | GP32: Qtr1 | GQ32: =(FR32/100)*GA32 -> 3.8902974e+10 | GR32: =+(GQ32/GL32) -> 0.033524523 | GU32: 1976 - Qtr1 | GV32: =_xlfn.XLOOKUP(GU32,$GO$13:$GO$288,$GR$13:$GR$288,"Not Found") -> 0.032237886 | GZ32: 26165 | HA32: 7.71
... P63: WY | Q63: 3.9 | S63: =+P63 -> WY | T63: =+Q63 -> 3.9 | W63: WY | X63: 3.4 | Z63: =W63 -> WY | AA63: =X63 -> 3.4 | BA63: 19085 | BB63: 58.8 | BF63: 18719 | BG63: 25.92 | BP63: 26024 | BQ63: 37.4 | BZ63: 18719 | CA63: 23.9 | CK63: 26024 | CL63: 41.1 | CV63: 18719 | CW63: 15.7 | DG63: 35521 | DH63: 97.9 | FQ63: Qtr2 | FR63: 16.239231 | FY63: Qtr2 | FZ63: 964154 | GA63: 964154000000 | GJ63: Qtr2 | GK63: 2215.4667 | GL63: 2.2154667e+12 | GO63: =IF(AND(LEFT(GP63,1)="Q",LEFT(GP62,1)<>"Q"),GP62&" - "&GP63,LEFT(GO62,4)&" - "&GP63) -> 1981 - Qtr2 | GP63: Qtr2 | GQ63: =(FR63/100)*GA63 -> 1.5657119e+11 | GR63: =+(GQ63/GL63) -> 0.070671879 | GU63: 1983 - Qtr4 | GV63: =_xlfn.XLOOKUP(GU63,$GO$13:$GO$288,$GR$13:$GR$288,"Not Found") -> 0.054992541 | GZ63: 26382 | HA63: 7.31
P64: Grand Total | Q64: 347.2 | W64: Grand Total | X64: 201.3 | BA64: 19115 | BB64: 59.1 | BF64: 18749 | BG64: 25.99 | BP64: 26054 | BQ64: 37.6 | BZ64: 18749 | CA64: 24 | CK64: 26054 | CL64: 41.3 | CV64: 18749 | CW64: 15.8 | DG64: 35551 | DH64: 98.2 | FQ64: Qtr3 | FR64: 17.38 | FY64: Qtr3 | FZ64: 981849 | GA64: 981849000000 | GJ64: Qtr3 | GK64: 2300.1667 | GL64: 2.3001667e+12 | GO64: =IF(AND(LEFT(GP64,1)="Q",LEFT(GP63,1)<>"Q"),GP63&" - "&GP64,LEFT(GO63,4)&" - "&GP64) -> 1981 - Qtr3 | GP64: Qtr3 | GQ64: =(FR64/100)*GA64 -> 1.7064536e+11 | GR64: =+(GQ64/GL64) -> 0.074188257 | GU64: 1984 - Qtr1 | GV64: =_xlfn.XLOOKUP(GU64,$GO$13:$GO$288,$GR$13:$GR$288,"Not Found") -> 0.054189009 | GZ64: 26389 | HA64: 7.23
BA65: 19146 | BB65: 59.1 | BF65: 18780 | BG65: 25.93 | BP65: 26085 | BQ65: 37.9 | BZ65: 18780 | CA65: 24.1 | CK65: 26085 | CL65: 41.5 | CV65: 18780 | CW65: 15.8 | DG65: 35582 | DH65: 98.5 | FQ65: Qtr4 | FR65: 17.735714 | FY65: Qtr4 | FZ65: 998261 | GA65: 998261000000 | GJ65: Qtr4 | GK65: 2337 | GL65: 2337000000000 | GO65: =IF(AND(LEFT(GP65,1)="Q",LEFT(GP64,1)<>"Q"),GP64&" - "&GP65,LEFT(GO64,4)&" - "&GP65) -> 1981 - Qtr4 | GP65: Qtr4 | GQ65: =(FR65/100)*GA65 -> 1.7704872e+11 | GR65: =+(GQ65/GL65) -> 0.075758973 | GU65: 1984 - Qtr2 | GV65: =_xlfn.XLOOKUP(GU65,$GO$13:$GO$288,$GR$13:$GR$288,"Not Found") -> 0.057229934 | GZ65: 26396 | HA65: 7.25
BA66: 19176 | BB66: 58.9 | BF66: 18810 | BG66: 25.91 | BP66: 26115 | BQ66: 38.1 | BZ66: 18810 | CA66: 24.1 | CK66: 26115 | CL66: 41.6 | CV66: 18810 | CW66: 15.8 | DG66: 35612 | DH66: 98.7 | FQ66: 1982 | FR66: 16.043654 | FY66: 1982 | FZ66: 1019020 | GA66: 1019020000000 | GJ66: 1982 | GK66: 2434.7167 | GL66: 2.4347167e+12 | GO66: =IF(AND(LEFT(GP66,1)="Q",LEFT(GP65,1)<>"Q"),GP65&" - "&GP66,LEFT(GO65,4)&" - "&GP66) -> 1981 - 1982 | GP66: 1982 | GQ66: =(FR66/100)*GA66 -> 1.6348804e+11 | GR66: =+(GQ66/GL66) -> 0.067148693 | GU66: 1984 - Qtr3 | GV66: =_xlfn.XLOOKUP(GU66,$GO$13:$GO$288,$GR$13:$GR$288,"Not Found") -> 0.059552493 | GZ66: 26403 | HA66: 7.29
BA67: 19207 | BB67: 58.7 | BF67: 18841 | BG67: 25.86 | BP67: 26146 | BQ67: 38.2 | BZ67: 18841 | CA67: 24.2 | CK67: 26146 | CL67: 41.6 | CV67: 18841 | CW67: 15.9 | DG67: 35643 | DH67: 98.7 | FQ67: Qtr1 | FR67: 17.414167 | FY67: Qtr1 | FZ67: 1007909 | GA67: 1007909000000 | GJ67: Qtr1 | GK67: 2372.2 | GL67: 2372200000000 | GO67: =IF(AND(LEFT(GP67,1)="Q",LEFT(GP66,1)<>"Q"),GP66&" - "&GP67,LEFT(GO66,4)&" - "&GP67) -> 1982 - Qtr1 | GP67: Qtr1 | GQ67: =(FR67/100)*GA67 -> 1.7551895e+11 | GR67: =+(GQ67/GL67) -> 0.073989947 | GU67: 1984 - Qtr4 | GV67: =_xlfn.XLOOKUP(GU67,$GO$13:$GO$288,$GR$13:$GR$288,"Not Found") -> 0.056729277 | GZ67: 26410 | HA67: 7.29
BA68: 19238 | BB68: 59.2 | BF68: 18872 | BG68: 26.03 | BP68: 26177 | BQ68: 38.4 | BZ68: 18872 | CA68: 24.4 | CK68: 26177 | CL68: 41.6 | CV68: 18872 | CW68: 15.9 | DG68: 35674 | DH68: 99 | FQ68: Qtr2 | FR68: 16.766154 | FY68: Qtr2 | FZ68: 1019260 | GA68: 1019260000000 | GJ68: Qtr2 | GK68: 2409.8 | GL68: 2409800000000 | GO68: =IF(AND(LEFT(GP68,1)="Q",LEFT(GP67,1)<>"Q"),GP67&" - "&GP68,LEFT(GO67,4)&" - "&GP68) -> 1982 - Qtr2 | GP68: Qtr2 | GQ68: =(FR68/100)*GA68 -> 1.708907e+11 | GR68: =+(GQ68/GL68) -> 0.070914889 | GU68: 1985 - Qtr1 | GV68: =_xlfn.XLOOKUP(GU68,$GO$13:$GO$288,$GR$13:$GR$288,"Not Found") -> 0.056464901 | GZ68: 26417 | HA68: 7.33
BA69: 19268 | BB69: 58.7 | BF69: 18902 | BG69: 26.16 | BP69: 26207 | BQ69: 38.5 | BZ69: 18902 | CA69: 24.5 | CK69: 26207 | CL69: 41.7 | CV69: 18902 | CW69: 16 | DG69: 35704 | DH69: 99.3 | FQ69: Qtr3 | FR69: 16.221538 | FY69: Qtr3 | FZ69: 1017736 | GA69: 1017736000000 | GJ69: Qtr3 | GK69: 2460.3333 | GL69: 2.4603333e+12 | GO69: =IF(AND(LEFT(GP69,1)="Q",LEFT(GP68,1)<>"Q"),GP68&" - "&GP69,LEFT(GO68,4)&" - "&GP69) -> 1982 - Qtr3 | GP69: Qtr3 | GQ69: =(FR69/100)*GA69 -> 1.6509244e+11 | GR69: =+(GQ69/GL69) -> 0.067101654 | GU69: 1985 - Qtr2 | GV69: =_xlfn.XLOOKUP(GU69,$GO$13:$GO$288,$GR$13:$GR$288,"Not Found") -> 0.055322306 | GZ69: 26424 | HA69: 7.33
BA70: 19299 | BB70: 59.1 | BF70: 18933 | BG70: 26.32 | BP70: 26238 | BQ70: 38.6 | BZ70: 18933 | CA70: 24.8 | CK70: 26238 | CL70: 41.9 | CV70: 18933 | CW70: 16.1 | DG70: 35735 | DH70: 99.5 | FQ70: Qtr4 | FR70: 14.032857 | FY70: Qtr4 | FZ70: 1031175 | GA70: 1031175000000 | GJ70: Qtr4 | GK70: 2496.5333 | GL70: 2.4965333e+12 | GO70: =IF(AND(LEFT(GP70,1)="Q",LEFT(GP69,1)<>"Q"),GP69&" - "&GP70,LEFT(GO69,4)&" - "&GP70) -> 1982 - Qtr4 | GP70: Qtr4 | GQ70: =(FR70/100)*GA70 -> 1.4470331e+11 | GR70: =+(GQ70/GL70) -> 0.057961699 | GU70: 1985 - Qtr3 | GV70: =_xlfn.XLOOKUP(GU70,$GO$13:$GO$288,$GR$13:$GR$288,"Not Found") -> 0.054559686 | GZ70: 26431 | HA70: 7.38
...

Sheet State names and code
B3: {"Alabama" | C3: AL | D3: ALUR} | E3: =LEFT(RIGHT(B3,LEN(B3)-10),LEN(RIGHT(B3,LEN(B3)-10))-1) -> Alabama
B4: {"Alaska" | C4: AK | D4: AKUR} | E4: =LEFT(RIGHT(B4,LEN(B4)-10),LEN(RIGHT(B4,LEN(B4)-10))-1) -> Alaska
B5: {"Arizona" | C5: AZ | D5: AZUR} | E5: =LEFT(RIGHT(B5,LEN(B5)-10),LEN(RIGHT(B5,LEN(B5)-10))-1) -> Arizona
B6: {"Arkansas" | C6: AR | D6: ARUR} | E6: =LEFT(RIGHT(B6,LEN(B6)-10),LEN(RIGHT(B6,LEN(B6)-10))-1) -> Arkansas
B7: {"California" | C7: CA | D7: CAUR} | E7: =LEFT(RIGHT(B7,LEN(B7)-10),LEN(RIGHT(B7,LEN(B7)-10))-1) -> California
B8: {"Colorado" | C8: CO | D8: COUR} | E8: =LEFT(RIGHT(B8,LEN(B8)-10),LEN(RIGHT(B8,LEN(B8)-10))-1) -> Colorado
B9: {"Connecticut" | C9: CT | D9: CTUR} | E9: =LEFT(RIGHT(B9,LEN(B9)-10),LEN(RIGHT(B9,LEN(B9)-10))-1) -> Connecticut
B10: {"Delaware" | C10: DE | D10: DEUR} | E10: =LEFT(RIGHT(B10,LEN(B10)-10),LEN(RIGHT(B10,LEN(B10)-10))-1) -> Delaware
B11: {"Florida" | C11: FL | D11: FLUR} | E11: =LEFT(RIGHT(B11,LEN(B11)-10),LEN(RIGHT(B11,LEN(B11)-10))-1) -> Florida
B12: {"Georgia" | C12: GA | D12: GAUR} | E12: =LEFT(RIGHT(B12,LEN(B12)-10),LEN(RIGHT(B12,LEN(B12)-10))-1) -> Georgia
B13: {"Hawaii" | C13: HI | D13: HIUR} | E13: =LEFT(RIGHT(B13,LEN(B13)-10),LEN(RIGHT(B13,LEN(B13)-10))-1) -> Hawaii
B14: {"Idaho" | C14: ID | D14: IDUR} | E14: =LEFT(RIGHT(B14,LEN(B14)-10),LEN(RIGHT(B14,LEN(B14)-10))-1) -> Idaho
... B52: {"Wyoming" | C52: WY | D52: WYUR} | E52: =LEFT(RIGHT(B52,LEN(B52)-10),LEN(RIGHT(B52,LEN(B52)-10))-1) -> Wyoming
